<?xml version="1.0" ?>
<!-- =================================================================================== -->
<!-- |    This document was autogenerated by xacro from seekurjr.urdf.xacro            | -->
<!-- |    EDITING THIS FILE BY HAND IS NOT RECOMMENDED                                 | -->
<!-- =================================================================================== -->
<robot name="skj" xmlns:controller="http://playerstage.sourceforge.net/gazebo/xmlschema/#controller" xmlns:interface="http://playerstage.sourceforge.net/gazebo/xmlschema/#interface" xmlns:sensor="http://playerstage.sourceforge.net/gazebo/xmlschema/#sensor">
  <!-- Chassis -->
  <link name="base_link">
    <inertial>
      <mass value="70"/>
      <origin xyz="0 0 0.3"/>
      <inertia ixx="0.3338" ixy="0.0" ixz="0.0" iyy="0.4783" iyz="0.0" izz="0.3338"/>
    </inertial>
    <visual>
      <origin rpy="0 0 0" xyz="0 0 0.3"/>
      <geometry name="skj_geom">
        <box size="1.000 0.600 0.376"/>
      </geometry>
      <material name="BodyBlue">
        <color rgba="0.0 0.0 1.0 1.0"/>
      </material>
    </visual>
    <collision>
      <origin rpy="0 0 0" xyz="0 0 0.3"/>
      <geometry>
        <box size="1.000 0.600 0.376"/>
      </geometry>
    </collision>
  </link>
  <gazebo reference="base_link">
    <material value="Gazebo/Blue"/>
  </gazebo>
  <link name="skj_front_left_wheel">
    <inertial>
      <mass value="4.2"/>
      <origin xyz="0 0 0.1"/>
      <inertia ixx="0.012411765597" ixy="0" ixz="0" iyy="0.015218160428" iyz="0" izz="0.011763977943"/>
    </inertial>
    <visual>
      <origin rpy="-1.570795 0 0" xyz="0 0 0.1"/>
      <geometry name="skj_wheel_geom">
        <cylinder length="0.2" radius="0.2"/>
      </geometry>
      <material name="WheelBlack">
        <color rgba="0.117 0.117 0.117 1"/>
      </material>
    </visual>
    <collision>
      <origin rpy="-1.57079635 0 0" xyz="0 0 0.1"/>
      <geometry>
        <cylinder length="0.2" radius="0.2"/>
      </geometry>
    </collision>
  </link>
  <gazebo reference="skj_front_left_wheel">
    <material value="Gazebo/Black"/>
  </gazebo>
  <joint name="skj_front_left_wheel_joint" type="continuous">
    <axis xyz="0 1 0"/>
    <anchor xyz="0 0 0"/>
    <limit effort="100" velocity="100"/>
    <joint_properties damping="0.7"/>
    <origin rpy="0 0 0" xyz="0.21 0.3 0.1"/>
    <parent link="base_link"/>
    <child link="skj_front_left_wheel"/>
  </joint>
  <gazebo reference="skj_front_left_wheel">
    <kp>1000000.0</kp>
    <!-- kp and kd for rubber -->
    <kd>100.0</kd>
    <mu1>1.0</mu1>
    <!-- was 10.0 -->
    <mu2>1.0</mu2>
    <!-- todo how to get these ODE params in: slip1, slip2 -->
    <!-- fdir1 0 1 0 /fdir1 -->
    <!-- see http://github.com/MobileRobots/amr-ros-config/issues/6 -->
    <maxVel>1.0</maxVel>
    <minDepth>0.00</minDepth>
    <material value="Gazebo/Black"/>
  </gazebo>
  <link name="skj_front_right_wheel">
    <inertial>
      <mass value="4.2"/>
      <origin xyz="0 0 0.1"/>
      <inertia ixx="0.012411765597" ixy="0" ixz="0" iyy="0.015218160428" iyz="0" izz="0.011763977943"/>
    </inertial>
    <visual>
      <origin rpy="-1.570795 0 0" xyz="0 0 0.1"/>
      <geometry name="skj_wheel_geom">
        <cylinder length="0.2" radius="0.2"/>
      </geometry>
      <material name="WheelBlack">
        <color rgba="0.117 0.117 0.117 1"/>
      </material>
    </visual>
    <collision>
      <origin rpy="-1.57079635 0 0" xyz="0 0 0.1"/>
      <geometry>
        <cylinder length="0.2" radius="0.2"/>
      </geometry>
    </collision>
  </link>
  <gazebo reference="skj_front_right_wheel">
    <material value="Gazebo/Black"/>
  </gazebo>
  <joint name="skj_front_right_wheel_joint" type="continuous">
    <axis xyz="0 1 0"/>
    <anchor xyz="0 0 0"/>
    <limit effort="100" velocity="100"/>
    <joint_properties damping="0.7"/>
    <origin rpy="0 0 0" xyz="0.21 -0.3 0.1"/>
    <parent link="base_link"/>
    <child link="skj_front_right_wheel"/>
  </joint>
  <gazebo reference="skj_front_right_wheel">
    <kp>1000000.0</kp>
    <!-- kp and kd for rubber -->
    <kd>100.0</kd>
    <mu1>1.0</mu1>
    <!-- was 10.0 -->
    <mu2>1.0</mu2>
    <!-- todo how to get these ODE params in: slip1, slip2 -->
    <!-- fdir1 0 1 0 /fdir1 -->
    <!-- see http://github.com/MobileRobots/amr-ros-config/issues/6 -->
    <maxVel>1.0</maxVel>
    <minDepth>0.00</minDepth>
    <material value="Gazebo/Black"/>
  </gazebo>
  <link name="skj_back_left_wheel">
    <inertial>
      <mass value="4.2"/>
      <origin xyz="0 0 0.1"/>
      <inertia ixx="0.012411765597" ixy="0" ixz="0" iyy="0.015218160428" iyz="0" izz="0.011763977943"/>
    </inertial>
    <visual>
      <origin rpy="-1.570795 0 0" xyz="0 0 0.1"/>
      <geometry name="skj_wheel_geom">
        <cylinder length="0.2" radius="0.2"/>
      </geometry>
      <material name="WheelBlack">
        <color rgba="0.117 0.117 0.117 1"/>
      </material>
    </visual>
    <collision>
      <origin rpy="-1.57079635 0 0" xyz="0 0 0.1"/>
      <geometry>
        <cylinder length="0.2" radius="0.2"/>
      </geometry>
    </collision>
  </link>
  <gazebo reference="skj_back_left_wheel">
    <material value="Gazebo/Black"/>
  </gazebo>
  <joint name="skj_back_left_wheel_joint" type="continuous">
    <axis xyz="0 1 0"/>
    <anchor xyz="0 0 0"/>
    <limit effort="100" velocity="100"/>
    <joint_properties damping="0.7"/>
    <origin rpy="0 0 0" xyz="-0.21 0.3 0.1"/>
    <parent link="base_link"/>
    <child link="skj_back_left_wheel"/>
  </joint>
  <gazebo reference="skj_back_left_wheel">
    <kp>1000000.0</kp>
    <!-- kp and kd for rubber -->
    <kd>100.0</kd>
    <mu1>1.0</mu1>
    <!-- was 10.0 -->
    <mu2>1.0</mu2>
    <!-- todo how to get these ODE params in: slip1, slip2 -->
    <!-- fdir1 0 1 0 /fdir1 -->
    <!-- see http://github.com/MobileRobots/amr-ros-config/issues/6 -->
    <maxVel>1.0</maxVel>
    <minDepth>0.00</minDepth>
    <material value="Gazebo/Black"/>
  </gazebo>
  <link name="skj_back_right_wheel">
    <inertial>
      <mass value="4.2"/>
      <origin xyz="0 0 0.1"/>
      <inertia ixx="0.012411765597" ixy="0" ixz="0" iyy="0.015218160428" iyz="0" izz="0.011763977943"/>
    </inertial>
    <visual>
      <origin rpy="-1.570795 0 0" xyz="0 0 0.1"/>
      <geometry name="skj_wheel_geom">
        <cylinder length="0.2" radius="0.2"/>
      </geometry>
      <material name="WheelBlack">
        <color rgba="0.117 0.117 0.117 1"/>
      </material>
    </visual>
    <collision>
      <origin rpy="-1.57079635 0 0" xyz="0 0 0.1"/>
      <geometry>
        <cylinder length="0.2" radius="0.2"/>
      </geometry>
    </collision>
  </link>
  <gazebo reference="skj_back_right_wheel">
    <material value="Gazebo/Black"/>
  </gazebo>
  <joint name="skj_back_right_wheel_joint" type="continuous">
    <axis xyz="0 1 0"/>
    <anchor xyz="0 0 0"/>
    <limit effort="100" velocity="100"/>
    <joint_properties damping="0.7"/>
    <origin rpy="0 0 0" xyz="-0.21 -0.3 0.1"/>
    <parent link="base_link"/>
    <child link="skj_back_right_wheel"/>
  </joint>
  <gazebo reference="skj_back_right_wheel">
    <kp>1000000.0</kp>
    <!-- kp and kd for rubber -->
    <kd>100.0</kd>
    <mu1>1.0</mu1>
    <!-- was 10.0 -->
    <mu2>1.0</mu2>
    <!-- todo how to get these ODE params in: slip1, slip2 -->
    <!-- fdir1 0 1 0 /fdir1 -->
    <!-- see http://github.com/MobileRobots/amr-ros-config/issues/6 -->
    <maxVel>1.0</maxVel>
    <minDepth>0.00</minDepth>
    <material value="Gazebo/Black"/>
  </gazebo>
  <gazebo>
    <plugin filename="libgazebo_ros_skid_steer_drive.so" name="skid_steer_drive_controller">
      <updateRate>100.0</updateRate>
      <robotNamespace>/</robotNamespace>
      <leftFrontJoint>skj_front_left_wheel_joint</leftFrontJoint>
      <rightFrontJoint>skj_front_right_wheel_joint</rightFrontJoint>
      <leftRearJoint>skj_back_left_wheel_joint</leftRearJoint>
      <rightRearJoint>skj_back_right_wheel_joint</rightRearJoint>
      <wheelSeparation>0.68</wheelSeparation>
      <wheelDiameter>0.40</wheelDiameter>
      <robotBaseFrame>base_link</robotBaseFrame>
      <torque>400</torque>
      <MaxForce>5.0</MaxForce>
      <commandTopic>cmd_vel</commandTopic>
      <odometryTopic>odom</odometryTopic>
      <odometryFrame>odom</odometryFrame>
      <broadcastTF>1</broadcastTF>
    </plugin>
  </gazebo>
</robot>

