<?xml version="1.0" ?>
<!-- =================================================================================== -->
<!-- |    This document was autogenerated by xacro from seekurjr.urdf.xacro            | -->
<!-- |    EDITING THIS FILE BY HAND IS NOT RECOMMENDED                                 | -->
<!-- =================================================================================== -->
<robot name="SeekurJr" xmlns:controller="http://playerstage.sourceforge.net/gazebo/xmlschema/#controller" xmlns:interface="http://playerstage.sourceforge.net/gazebo/xmlschema/#interface" xmlns:sensor="http://playerstage.sourceforge.net/gazebo/xmlschema/#sensor">
  <link name="base_link">
    <visual>
      <origin rpy="0 0 0" xyz="0 0 0.3"/>
      <geometry name="skj_geom_1">
        <box size="0.400 0.620 0.286"/>
      </geometry>
      <material name="BodyBlue">
        <color rgba="0.0 0.0 1.0 1.0"/>
      </material>
    </visual>
    <visual>
      <origin rpy="0 0 0" xyz="0.2 0 0.3"/>
      <geometry name="skj_geom_2">
        <cylinder length="0.286" radius="0.31"/>
      </geometry>
      <material name="BodyBlue">
        <color rgba="0.0 0.0 1.0 1.0"/>
      </material>
    </visual>
    <visual>
      <origin rpy="0 0 0" xyz="-0.2 0 0.3"/>
      <geometry name="skj_geom_2">
        <cylinder length="0.286" radius="0.31"/>
      </geometry>
      <material name="BodyBlue">
        <color rgba="0.0 0.0 1.0 1.0"/>
      </material>
    </visual>
  </link>
  <link name="laser">
    <visual>
      <geometry name="skj_laser">
        <cylinder length="0.1" radius="0.05"/>
      </geometry>
      <material name="LaserWhite">
        <color rgba="1.0 1.0 1.0 1.0"/>
      </material>
    </visual>
  </link>
  <joint name="base_to_laser" type="continuous">
    <origin rpy="0 0 0" xyz="0.51 0 0.3"/>
    <parent link="base_link"/>
    <child link="laser"/>
  </joint>
  <link name="skj_front_left_wheel">
    <visual>
      <origin rpy="-1.570795 0 0" xyz="0 0 0.1"/>
      <geometry name="skj_wheel_geom">
        <cylinder length="0.2" radius="0.2"/>
      </geometry>
      <material name="WheelBlack">
        <color rgba="0.117 0.117 0.117 1"/>
      </material>
    </visual>
    <visual>
      <origin rpy="-1.570795 0 0" xyz="0 0 0.1"/>
      <geometry name="skj_wheel_geom">
        <cylinder length="0.21" radius="0.05"/>
      </geometry>
      <material name="WheelWhite">
        <color rgba="1 1 1 1"/>
      </material>
    </visual>
  </link>
  <joint name="skj_front_left_wheel_joint" type="continuous">
    <axis xyz="0 1 0"/>
    <anchor xyz="0 0 0"/>
    <limit effort="100" velocity="100"/>
    <joint_properties damping="0.7"/>
    <origin rpy="0 0 0" xyz="0.21 0.3 0.1"/>
    <parent link="base_link"/>
    <child link="skj_front_left_wheel"/>
  </joint>
  <link name="skj_front_right_wheel">
    <visual>
      <origin rpy="-1.570795 0 0" xyz="0 0 0.1"/>
      <geometry name="skj_wheel_geom">
        <cylinder length="0.2" radius="0.2"/>
      </geometry>
      <material name="WheelBlack">
        <color rgba="0.117 0.117 0.117 1"/>
      </material>
    </visual>
    <visual>
      <origin rpy="-1.570795 0 0" xyz="0 0 0.1"/>
      <geometry name="skj_wheel_geom">
        <cylinder length="0.21" radius="0.05"/>
      </geometry>
      <material name="WheelWhite">
        <color rgba="1 1 1 1"/>
      </material>
    </visual>
  </link>
  <joint name="skj_front_right_wheel_joint" type="continuous">
    <axis xyz="0 1 0"/>
    <anchor xyz="0 0 0"/>
    <limit effort="100" velocity="100"/>
    <joint_properties damping="0.7"/>
    <origin rpy="0 0 0" xyz="0.21 -0.3 0.1"/>
    <parent link="base_link"/>
    <child link="skj_front_right_wheel"/>
  </joint>
  <link name="skj_back_left_wheel">
    <visual>
      <origin rpy="-1.570795 0 0" xyz="0 0 0.1"/>
      <geometry name="skj_wheel_geom">
        <cylinder length="0.2" radius="0.2"/>
      </geometry>
      <material name="WheelBlack">
        <color rgba="0.117 0.117 0.117 1"/>
      </material>
    </visual>
    <visual>
      <origin rpy="-1.570795 0 0" xyz="0 0 0.1"/>
      <geometry name="skj_wheel_geom">
        <cylinder length="0.21" radius="0.05"/>
      </geometry>
      <material name="WheelWhite">
        <color rgba="1 1 1 1"/>
      </material>
    </visual>
  </link>
  <joint name="skj_back_left_wheel_joint" type="continuous">
    <axis xyz="0 1 0"/>
    <anchor xyz="0 0 0"/>
    <limit effort="100" velocity="100"/>
    <joint_properties damping="0.7"/>
    <origin rpy="0 0 0" xyz="-0.21 0.3 0.1"/>
    <parent link="base_link"/>
    <child link="skj_back_left_wheel"/>
  </joint>
  <link name="skj_back_right_wheel">
    <visual>
      <origin rpy="-1.570795 0 0" xyz="0 0 0.1"/>
      <geometry name="skj_wheel_geom">
        <cylinder length="0.2" radius="0.2"/>
      </geometry>
      <material name="WheelBlack">
        <color rgba="0.117 0.117 0.117 1"/>
      </material>
    </visual>
    <visual>
      <origin rpy="-1.570795 0 0" xyz="0 0 0.1"/>
      <geometry name="skj_wheel_geom">
        <cylinder length="0.21" radius="0.05"/>
      </geometry>
      <material name="WheelWhite">
        <color rgba="1 1 1 1"/>
      </material>
    </visual>
  </link>
  <joint name="skj_back_right_wheel_joint" type="continuous">
    <axis xyz="0 1 0"/>
    <anchor xyz="0 0 0"/>
    <limit effort="100" velocity="100"/>
    <joint_properties damping="0.7"/>
    <origin rpy="0 0 0" xyz="-0.21 -0.3 0.1"/>
    <parent link="base_link"/>
    <child link="skj_back_right_wheel"/>
  </joint>
</robot>

